WARNING  2025-07-23 10:40:51,912  D:\ForcastingProject\venv97\lib\site-packages\django\utils\log.py  log  222  20796  Not Found: / 

WARNING  2025-07-23 10:40:51,924  D:\ForcastingProject\venv97\lib\site-packages\django\utils\log.py  log  222  11308  Not Found: / 

WARNING  2025-07-23 10:40:51,984  D:\ForcastingProject\venv97\lib\site-packages\django\utils\log.py  log  222  11308  Not Found: /favicon.ico 

WARNING  2025-07-23 10:40:51,995  D:\ForcastingProject\venv97\lib\site-packages\django\utils\log.py  log  222  11308  Not Found: /favicon.ico 

WARNING  2025-07-23 10:45:54,668  D:\ForcastingProject\venv97\lib\site-packages\django\utils\log.py  log  222  3400  Unauthorized: /user/login/ 

ERROR  2025-07-23 10:51:34,627  D:\ForcastingProject\venv97\lib\site-packages\django\utils\log.py  log  222  20472  Internal Server Error: /data/ 
Traceback (most recent call last):
  File "D:\ForcastingProject\venv97\lib\site-packages\django\core\handlers\exception.py", line 34, in inner
    response = get_response(request)
  File "D:\ForcastingProject\venv97\lib\site-packages\django\core\handlers\base.py", line 115, in _get_response
    response = self.process_exception_by_middleware(e, request)
  File "D:\ForcastingProject\venv97\lib\site-packages\django\core\handlers\base.py", line 113, in _get_response
    response = wrapped_callback(request, *callback_args, **callback_kwargs)
  File "D:\ForcastingProject\venv97\lib\site-packages\django\views\decorators\csrf.py", line 54, in wrapped_view
    return view_func(*args, **kwargs)
  File "D:\ForcastingProject\venv97\lib\site-packages\django\views\generic\base.py", line 71, in view
    return self.dispatch(request, *args, **kwargs)
  File "D:\ForcastingProject\venv97\lib\site-packages\rest_framework\views.py", line 505, in dispatch
    response = self.handle_exception(exc)
  File "D:\ForcastingProject\venv97\lib\site-packages\rest_framework\views.py", line 465, in handle_exception
    self.raise_uncaught_exception(exc)
  File "D:\ForcastingProject\venv97\lib\site-packages\rest_framework\views.py", line 476, in raise_uncaught_exception
    raise exc
  File "D:\ForcastingProject\venv97\lib\site-packages\rest_framework\views.py", line 502, in dispatch
    response = handler(request, *args, **kwargs)
  File "D:\ForcastingProject\datas\views\views.py", line 328, in post
    individual_columns = missing_weeks(individual_columns)
  File "D:\ForcastingProject\datas\views\views.py", line 317, in missing_weeks
    [lst.append(x) for x in range(lst[0], lst[-1] + 1) if x not in lst]
IndexError: list index out of range
ERROR  2025-07-23 11:10:00,183  D:\ForcastingProject\venv97\lib\site-packages\django\utils\log.py  log  222  13152  Internal Server Error: /data/ 

ERROR  2025-07-23 11:34:07,880  D:\ForcastingProject\venv97\lib\site-packages\django\utils\log.py  log  222  15532  Internal Server Error: /data/ 

ERROR  2025-07-23 11:34:28,981  D:\ForcastingProject\venv97\lib\site-packages\django\utils\log.py  log  222  20700  Internal Server Error: /data/ 

ERROR  2025-07-23 11:37:49,136  D:\ForcastingProject\venv97\lib\site-packages\django\utils\log.py  log  222  19552  Internal Server Error: /data/ 

ERROR  2025-07-23 11:38:06,502  D:\ForcastingProject\venv97\lib\site-packages\django\utils\log.py  log  222  19552  Internal Server Error: /data/ 

ERROR  2025-07-23 11:38:46,082  D:\ForcastingProject\venv97\lib\site-packages\django\utils\log.py  log  222  22704  Internal Server Error: /data/ 

ERROR  2025-07-23 11:39:02,428  D:\ForcastingProject\venv97\lib\site-packages\django\utils\log.py  log  222  22704  Internal Server Error: /data/ 

ERROR  2025-07-23 11:39:28,757  D:\ForcastingProject\venv97\lib\site-packages\django\utils\log.py  log  222  22704  Internal Server Error: /data/ 

ERROR  2025-07-23 11:44:33,408  D:\ForcastingProject\venv97\lib\site-packages\django\utils\log.py  log  222  8992  Internal Server Error: /data/ 

ERROR  2025-07-23 11:45:38,628  D:\ForcastingProject\venv97\lib\site-packages\django\utils\log.py  log  222  8992  Internal Server Error: /data/ 

ERROR  2025-07-23 11:47:59,423  D:\ForcastingProject\venv97\lib\site-packages\django\utils\log.py  log  222  8992  Internal Server Error: /data/ 

WARNING  2025-07-23 12:26:59,343  D:\ForcastingProject\venv97\lib\site-packages\django\utils\log.py  log  222  21588  Unauthorized: /data/ 

WARNING  2025-07-23 12:26:59,367  D:\ForcastingProject\venv97\lib\site-packages\django\utils\log.py  log  222  21588  Unauthorized: /datesofinputfiles/ 

ERROR  2025-07-23 12:36:35,575  D:\ForcastingProject\venv97\lib\site-packages\django\utils\log.py  log  222  23076  Internal Server Error: /data/ 

ERROR  2025-07-23 12:36:59,900  D:\ForcastingProject\venv97\lib\site-packages\django\utils\log.py  log  222  23076  Internal Server Error: /data/ 

ERROR  2025-07-23 12:38:58,344  D:\ForcastingProject\venv97\lib\site-packages\django\utils\log.py  log  222  21696  Internal Server Error: /data/ 

ERROR  2025-07-23 12:40:40,313  D:\ForcastingProject\venv97\lib\site-packages\django\utils\log.py  log  222  21696  Internal Server Error: /data/ 

ERROR  2025-07-23 12:42:54,883  D:\ForcastingProject\venv97\lib\site-packages\django\utils\log.py  log  222  21696  Internal Server Error: /data/ 

ERROR  2025-07-23 12:44:53,518  D:\ForcastingProject\venv97\lib\site-packages\django\utils\log.py  log  222  20616  Internal Server Error: /data/ 

ERROR  2025-07-23 12:57:00,096  D:\ForcastingProject\venv97\lib\site-packages\django\utils\log.py  log  222  24124  Internal Server Error: /data/ 

ERROR  2025-07-23 12:58:55,259  D:\ForcastingProject\venv97\lib\site-packages\django\utils\log.py  log  222  24124  Internal Server Error: /data/ 

ERROR  2025-07-23 13:01:21,319  D:\ForcastingProject\venv97\lib\site-packages\django\utils\log.py  log  222  5920  Internal Server Error: /data/ 

ERROR  2025-07-23 13:01:36,554  D:\ForcastingProject\venv97\lib\site-packages\django\utils\log.py  log  222  5920  Internal Server Error: /data/ 

ERROR  2025-07-23 13:03:30,040  D:\ForcastingProject\venv97\lib\site-packages\django\utils\log.py  log  222  24320  Internal Server Error: /data/ 

ERROR  2025-07-23 13:06:01,175  D:\ForcastingProject\venv97\lib\site-packages\django\utils\log.py  log  222  17420  Internal Server Error: /data/ 

ERROR  2025-07-23 13:07:00,622  D:\ForcastingProject\venv97\lib\site-packages\django\utils\log.py  log  222  17420  Internal Server Error: /data/ 

ERROR  2025-07-23 13:09:24,148  D:\ForcastingProject\venv97\lib\site-packages\django\utils\log.py  log  222  8576  Internal Server Error: /data/ 

ERROR  2025-07-23 13:12:04,486  D:\ForcastingProject\venv97\lib\site-packages\django\utils\log.py  log  222  19100  Internal Server Error: /data/ 

ERROR  2025-07-23 13:12:30,690  D:\ForcastingProject\venv97\lib\site-packages\django\utils\log.py  log  222  19100  Internal Server Error: /data/ 

ERROR  2025-07-23 13:13:56,154  D:\ForcastingProject\venv97\lib\site-packages\django\utils\log.py  log  222  15252  Internal Server Error: /data/ 

ERROR  2025-07-23 13:15:33,094  D:\ForcastingProject\venv97\lib\site-packages\django\utils\log.py  log  222  13132  Internal Server Error: /data/ 

ERROR  2025-07-23 13:18:07,204  D:\ForcastingProject\venv97\lib\site-packages\django\utils\log.py  log  222  14768  Internal Server Error: /data/ 

ERROR  2025-07-23 13:18:30,910  D:\ForcastingProject\venv97\lib\site-packages\django\utils\log.py  log  222  14768  Internal Server Error: /data/ 

WARNING  2025-07-23 14:21:13,328  D:\ForcastingProject\venv97\lib\site-packages\django\utils\log.py  log  222  11308  Unauthorized: /data/ 

WARNING  2025-07-23 14:21:13,334  D:\ForcastingProject\venv97\lib\site-packages\django\utils\log.py  log  222  11308  Unauthorized: /datesofinputfiles/ 

ERROR  2025-07-23 14:22:58,643  D:\ForcastingProject\venv97\lib\site-packages\django\utils\log.py  log  222  9136  Internal Server Error: /data/ 

ERROR  2025-07-23 14:25:12,642  D:\ForcastingProject\venv97\lib\site-packages\django\utils\log.py  log  222  23400  Internal Server Error: /data/ 

ERROR  2025-07-23 14:28:40,751  D:\ForcastingProject\venv97\lib\site-packages\django\utils\log.py  log  222  19460  Internal Server Error: /data/ 

ERROR  2025-07-23 14:30:26,828  D:\ForcastingProject\venv97\lib\site-packages\django\utils\log.py  log  222  2572  Internal Server Error: /data/ 

ERROR  2025-07-23 15:08:12,819  E:\DemandForecast\Backend\venv\lib\site-packages\django\utils\log.py  log  222  5464  Internal Server Error: /cpastokechartdata/ 
Traceback (most recent call last):
  File "E:\DemandForecast\Backend\venv\lib\site-packages\django\core\handlers\exception.py", line 34, in inner
    response = get_response(request)
  File "E:\DemandForecast\Backend\venv\lib\site-packages\django\core\handlers\base.py", line 115, in _get_response
    response = self.process_exception_by_middleware(e, request)
  File "E:\DemandForecast\Backend\venv\lib\site-packages\django\core\handlers\base.py", line 113, in _get_response
    response = wrapped_callback(request, *callback_args, **callback_kwargs)
  File "E:\DemandForecast\Backend\venv\lib\site-packages\django\views\decorators\csrf.py", line 54, in wrapped_view
    return view_func(*args, **kwargs)
  File "E:\DemandForecast\Backend\venv\lib\site-packages\django\views\generic\base.py", line 71, in view
    return self.dispatch(request, *args, **kwargs)
  File "E:\DemandForecast\Backend\venv\lib\site-packages\rest_framework\views.py", line 505, in dispatch
    response = self.handle_exception(exc)
  File "E:\DemandForecast\Backend\venv\lib\site-packages\rest_framework\views.py", line 465, in handle_exception
    self.raise_uncaught_exception(exc)
  File "E:\DemandForecast\Backend\venv\lib\site-packages\rest_framework\views.py", line 476, in raise_uncaught_exception
    raise exc
  File "E:\DemandForecast\Backend\venv\lib\site-packages\rest_framework\views.py", line 502, in dispatch
    response = handler(request, *args, **kwargs)
  File "E:\DemandForecast\Backend\.\datas\views\chartViews.py", line 220, in get
    names = ['Total', str(columns[4]) + '-' + str(columns[7]), str(columns[8]) + '-' + str(columns[11]), 'End']
IndexError: list index out of range
ERROR  2025-07-23 15:15:04,758  E:\DemandForecast\Backend\venv\lib\site-packages\django\utils\log.py  log  222  9792  Internal Server Error: /cpastokechartdata/ 
Traceback (most recent call last):
  File "E:\DemandForecast\Backend\venv\lib\site-packages\django\core\handlers\exception.py", line 34, in inner
    response = get_response(request)
  File "E:\DemandForecast\Backend\venv\lib\site-packages\django\core\handlers\base.py", line 115, in _get_response
    response = self.process_exception_by_middleware(e, request)
  File "E:\DemandForecast\Backend\venv\lib\site-packages\django\core\handlers\base.py", line 113, in _get_response
    response = wrapped_callback(request, *callback_args, **callback_kwargs)
  File "E:\DemandForecast\Backend\venv\lib\site-packages\django\views\decorators\csrf.py", line 54, in wrapped_view
    return view_func(*args, **kwargs)
  File "E:\DemandForecast\Backend\venv\lib\site-packages\django\views\generic\base.py", line 71, in view
    return self.dispatch(request, *args, **kwargs)
  File "E:\DemandForecast\Backend\venv\lib\site-packages\rest_framework\views.py", line 505, in dispatch
    response = self.handle_exception(exc)
  File "E:\DemandForecast\Backend\venv\lib\site-packages\rest_framework\views.py", line 465, in handle_exception
    self.raise_uncaught_exception(exc)
  File "E:\DemandForecast\Backend\venv\lib\site-packages\rest_framework\views.py", line 476, in raise_uncaught_exception
    raise exc
  File "E:\DemandForecast\Backend\venv\lib\site-packages\rest_framework\views.py", line 502, in dispatch
    response = handler(request, *args, **kwargs)
  File "E:\DemandForecast\Backend\.\datas\views\chartViews.py", line 220, in get
    names = ['Total', str(columns[4]) + '-' + str(columns[7]), str(columns[8]) + '-' + str(columns[11]), 'End']
IndexError: list index out of range
ERROR  2025-07-24 16:07:37,910  E:\DemandForecast\Backend\venv\lib\site-packages\django\utils\log.py  log  222  16576  Internal Server Error: /cpastokechartdata/ 
Traceback (most recent call last):
  File "E:\DemandForecast\Backend\venv\lib\site-packages\django\core\handlers\exception.py", line 34, in inner
    response = get_response(request)
  File "E:\DemandForecast\Backend\venv\lib\site-packages\django\core\handlers\base.py", line 115, in _get_response
    response = self.process_exception_by_middleware(e, request)
  File "E:\DemandForecast\Backend\venv\lib\site-packages\django\core\handlers\base.py", line 113, in _get_response
    response = wrapped_callback(request, *callback_args, **callback_kwargs)
  File "E:\DemandForecast\Backend\venv\lib\site-packages\django\views\decorators\csrf.py", line 54, in wrapped_view
    return view_func(*args, **kwargs)
  File "E:\DemandForecast\Backend\venv\lib\site-packages\django\views\generic\base.py", line 71, in view
    return self.dispatch(request, *args, **kwargs)
  File "E:\DemandForecast\Backend\venv\lib\site-packages\rest_framework\views.py", line 505, in dispatch
    response = self.handle_exception(exc)
  File "E:\DemandForecast\Backend\venv\lib\site-packages\rest_framework\views.py", line 465, in handle_exception
    self.raise_uncaught_exception(exc)
  File "E:\DemandForecast\Backend\venv\lib\site-packages\rest_framework\views.py", line 476, in raise_uncaught_exception
    raise exc
  File "E:\DemandForecast\Backend\venv\lib\site-packages\rest_framework\views.py", line 502, in dispatch
    response = handler(request, *args, **kwargs)
  File "E:\DemandForecast\Backend\.\datas\views\chartViews.py", line 220, in get
    names = ['Total', str(columns[4]) + '-' + str(columns[7]), str(columns[8]) + '-' + str(columns[11]), 'End']
IndexError: list index out of range
ERROR  2025-07-25 09:10:33,099  E:\DemandForecast\Backend\venv\lib\site-packages\django\utils\log.py  log  222  17708  Internal Server Error: /cpastokechartdata/ 
Traceback (most recent call last):
  File "E:\DemandForecast\Backend\venv\lib\site-packages\django\core\handlers\exception.py", line 34, in inner
    response = get_response(request)
  File "E:\DemandForecast\Backend\venv\lib\site-packages\django\core\handlers\base.py", line 115, in _get_response
    response = self.process_exception_by_middleware(e, request)
  File "E:\DemandForecast\Backend\venv\lib\site-packages\django\core\handlers\base.py", line 113, in _get_response
    response = wrapped_callback(request, *callback_args, **callback_kwargs)
  File "E:\DemandForecast\Backend\venv\lib\site-packages\django\views\decorators\csrf.py", line 54, in wrapped_view
    return view_func(*args, **kwargs)
  File "E:\DemandForecast\Backend\venv\lib\site-packages\django\views\generic\base.py", line 71, in view
    return self.dispatch(request, *args, **kwargs)
  File "E:\DemandForecast\Backend\venv\lib\site-packages\rest_framework\views.py", line 505, in dispatch
    response = self.handle_exception(exc)
  File "E:\DemandForecast\Backend\venv\lib\site-packages\rest_framework\views.py", line 465, in handle_exception
    self.raise_uncaught_exception(exc)
  File "E:\DemandForecast\Backend\venv\lib\site-packages\rest_framework\views.py", line 476, in raise_uncaught_exception
    raise exc
  File "E:\DemandForecast\Backend\venv\lib\site-packages\rest_framework\views.py", line 502, in dispatch
    response = handler(request, *args, **kwargs)
  File "E:\DemandForecast\Backend\.\datas\views\chartViews.py", line 220, in get
    names = ['Total', str(columns[4]) + '-' + str(columns[7]), str(columns[8]) + '-' + str(columns[11]), 'End']
IndexError: list index out of range
WARNING  2025-07-25 12:01:39,645  E:\DemandForecast\Backend\venv\lib\site-packages\django\utils\log.py  log  222  12380  Unauthorized: /data/ 

WARNING  2025-07-25 12:01:39,645  E:\DemandForecast\Backend\venv\lib\site-packages\django\utils\log.py  log  222  17616  Unauthorized: /datesofinputfiles/ 

ERROR  2025-07-25 12:01:50,536  E:\DemandForecast\Backend\venv\lib\site-packages\django\utils\log.py  log  222  4984  Internal Server Error: /cpastokechartdata/ 
Traceback (most recent call last):
  File "E:\DemandForecast\Backend\venv\lib\site-packages\django\core\handlers\exception.py", line 34, in inner
    response = get_response(request)
  File "E:\DemandForecast\Backend\venv\lib\site-packages\django\core\handlers\base.py", line 115, in _get_response
    response = self.process_exception_by_middleware(e, request)
  File "E:\DemandForecast\Backend\venv\lib\site-packages\django\core\handlers\base.py", line 113, in _get_response
    response = wrapped_callback(request, *callback_args, **callback_kwargs)
  File "E:\DemandForecast\Backend\venv\lib\site-packages\django\views\decorators\csrf.py", line 54, in wrapped_view
    return view_func(*args, **kwargs)
  File "E:\DemandForecast\Backend\venv\lib\site-packages\django\views\generic\base.py", line 71, in view
    return self.dispatch(request, *args, **kwargs)
  File "E:\DemandForecast\Backend\venv\lib\site-packages\rest_framework\views.py", line 505, in dispatch
    response = self.handle_exception(exc)
  File "E:\DemandForecast\Backend\venv\lib\site-packages\rest_framework\views.py", line 465, in handle_exception
    self.raise_uncaught_exception(exc)
  File "E:\DemandForecast\Backend\venv\lib\site-packages\rest_framework\views.py", line 476, in raise_uncaught_exception
    raise exc
  File "E:\DemandForecast\Backend\venv\lib\site-packages\rest_framework\views.py", line 502, in dispatch
    response = handler(request, *args, **kwargs)
  File "E:\DemandForecast\Backend\.\datas\views\chartViews.py", line 220, in get
    names = ['Total', str(columns[4]) + '-' + str(columns[7]), str(columns[8]) + '-' + str(columns[11]), 'End']
IndexError: list index out of range
ERROR  2025-07-25 17:15:12,468  E:\DemandForecast\Backend\venv\lib\site-packages\django\utils\log.py  log  222  12932  Internal Server Error: /cpastokechartdata/ 
Traceback (most recent call last):
  File "E:\DemandForecast\Backend\venv\lib\site-packages\django\core\handlers\exception.py", line 34, in inner
    response = get_response(request)
  File "E:\DemandForecast\Backend\venv\lib\site-packages\django\core\handlers\base.py", line 115, in _get_response
    response = self.process_exception_by_middleware(e, request)
  File "E:\DemandForecast\Backend\venv\lib\site-packages\django\core\handlers\base.py", line 113, in _get_response
    response = wrapped_callback(request, *callback_args, **callback_kwargs)
  File "E:\DemandForecast\Backend\venv\lib\site-packages\django\views\decorators\csrf.py", line 54, in wrapped_view
    return view_func(*args, **kwargs)
  File "E:\DemandForecast\Backend\venv\lib\site-packages\django\views\generic\base.py", line 71, in view
    return self.dispatch(request, *args, **kwargs)
  File "E:\DemandForecast\Backend\venv\lib\site-packages\rest_framework\views.py", line 505, in dispatch
    response = self.handle_exception(exc)
  File "E:\DemandForecast\Backend\venv\lib\site-packages\rest_framework\views.py", line 465, in handle_exception
    self.raise_uncaught_exception(exc)
  File "E:\DemandForecast\Backend\venv\lib\site-packages\rest_framework\views.py", line 476, in raise_uncaught_exception
    raise exc
  File "E:\DemandForecast\Backend\venv\lib\site-packages\rest_framework\views.py", line 502, in dispatch
    response = handler(request, *args, **kwargs)
  File "E:\DemandForecast\Backend\.\datas\views\chartViews.py", line 220, in get
    names = ['Total', str(columns[4]) + '-' + str(columns[7]), str(columns[8]) + '-' + str(columns[11]), 'End']
IndexError: list index out of range
ERROR  2025-07-27 06:52:18,622  E:\DemandForecast\Backend\venv\lib\site-packages\django\utils\log.py  log  222  6408  Internal Server Error: /cpastokechartdata/ 
Traceback (most recent call last):
  File "E:\DemandForecast\Backend\venv\lib\site-packages\django\core\handlers\exception.py", line 34, in inner
    response = get_response(request)
  File "E:\DemandForecast\Backend\venv\lib\site-packages\django\core\handlers\base.py", line 115, in _get_response
    response = self.process_exception_by_middleware(e, request)
  File "E:\DemandForecast\Backend\venv\lib\site-packages\django\core\handlers\base.py", line 113, in _get_response
    response = wrapped_callback(request, *callback_args, **callback_kwargs)
  File "E:\DemandForecast\Backend\venv\lib\site-packages\django\views\decorators\csrf.py", line 54, in wrapped_view
    return view_func(*args, **kwargs)
  File "E:\DemandForecast\Backend\venv\lib\site-packages\django\views\generic\base.py", line 71, in view
    return self.dispatch(request, *args, **kwargs)
  File "E:\DemandForecast\Backend\venv\lib\site-packages\rest_framework\views.py", line 505, in dispatch
    response = self.handle_exception(exc)
  File "E:\DemandForecast\Backend\venv\lib\site-packages\rest_framework\views.py", line 465, in handle_exception
    self.raise_uncaught_exception(exc)
  File "E:\DemandForecast\Backend\venv\lib\site-packages\rest_framework\views.py", line 476, in raise_uncaught_exception
    raise exc
  File "E:\DemandForecast\Backend\venv\lib\site-packages\rest_framework\views.py", line 502, in dispatch
    response = handler(request, *args, **kwargs)
  File "E:\DemandForecast\Backend\.\datas\views\chartViews.py", line 220, in get
    names = ['Total', str(columns[4]) + '-' + str(columns[7]), str(columns[8]) + '-' + str(columns[11]), 'End']
IndexError: list index out of range
ERROR  2025-07-27 07:26:01,672  E:\DemandForecast\Backend\venv\lib\site-packages\django\utils\log.py  log  222  3132  Internal Server Error: /cpastokechartdata/ 
Traceback (most recent call last):
  File "E:\DemandForecast\Backend\venv\lib\site-packages\django\core\handlers\exception.py", line 34, in inner
    response = get_response(request)
  File "E:\DemandForecast\Backend\venv\lib\site-packages\django\core\handlers\base.py", line 115, in _get_response
    response = self.process_exception_by_middleware(e, request)
  File "E:\DemandForecast\Backend\venv\lib\site-packages\django\core\handlers\base.py", line 113, in _get_response
    response = wrapped_callback(request, *callback_args, **callback_kwargs)
  File "E:\DemandForecast\Backend\venv\lib\site-packages\django\views\decorators\csrf.py", line 54, in wrapped_view
    return view_func(*args, **kwargs)
  File "E:\DemandForecast\Backend\venv\lib\site-packages\django\views\generic\base.py", line 71, in view
    return self.dispatch(request, *args, **kwargs)
  File "E:\DemandForecast\Backend\venv\lib\site-packages\rest_framework\views.py", line 505, in dispatch
    response = self.handle_exception(exc)
  File "E:\DemandForecast\Backend\venv\lib\site-packages\rest_framework\views.py", line 465, in handle_exception
    self.raise_uncaught_exception(exc)
  File "E:\DemandForecast\Backend\venv\lib\site-packages\rest_framework\views.py", line 476, in raise_uncaught_exception
    raise exc
  File "E:\DemandForecast\Backend\venv\lib\site-packages\rest_framework\views.py", line 502, in dispatch
    response = handler(request, *args, **kwargs)
  File "E:\DemandForecast\Backend\.\datas\views\chartViews.py", line 220, in get
    names = ['Total', str(columns[4]) + '-' + str(columns[7]), str(columns[8]) + '-' + str(columns[11]), 'End']
IndexError: list index out of range
ERROR  2025-07-27 08:09:48,675  E:\DemandForecast\Backend\venv\lib\site-packages\django\utils\log.py  log  222  3456  Internal Server Error: /cpastokechartdata/ 
Traceback (most recent call last):
  File "E:\DemandForecast\Backend\venv\lib\site-packages\django\core\handlers\exception.py", line 34, in inner
    response = get_response(request)
  File "E:\DemandForecast\Backend\venv\lib\site-packages\django\core\handlers\base.py", line 115, in _get_response
    response = self.process_exception_by_middleware(e, request)
  File "E:\DemandForecast\Backend\venv\lib\site-packages\django\core\handlers\base.py", line 113, in _get_response
    response = wrapped_callback(request, *callback_args, **callback_kwargs)
  File "E:\DemandForecast\Backend\venv\lib\site-packages\django\views\decorators\csrf.py", line 54, in wrapped_view
    return view_func(*args, **kwargs)
  File "E:\DemandForecast\Backend\venv\lib\site-packages\django\views\generic\base.py", line 71, in view
    return self.dispatch(request, *args, **kwargs)
  File "E:\DemandForecast\Backend\venv\lib\site-packages\rest_framework\views.py", line 505, in dispatch
    response = self.handle_exception(exc)
  File "E:\DemandForecast\Backend\venv\lib\site-packages\rest_framework\views.py", line 465, in handle_exception
    self.raise_uncaught_exception(exc)
  File "E:\DemandForecast\Backend\venv\lib\site-packages\rest_framework\views.py", line 476, in raise_uncaught_exception
    raise exc
  File "E:\DemandForecast\Backend\venv\lib\site-packages\rest_framework\views.py", line 502, in dispatch
    response = handler(request, *args, **kwargs)
  File "E:\DemandForecast\Backend\.\datas\views\chartViews.py", line 220, in get
    names = ['Total', str(columns[4]) + '-' + str(columns[7]), str(columns[8]) + '-' + str(columns[11]), 'End']
IndexError: list index out of range
ERROR  2025-07-29 16:59:09,559  E:\DemandForecast\Backend\venv\lib\site-packages\django\utils\log.py  log  222  12396  Internal Server Error: /cpastokechartdata/ 
Traceback (most recent call last):
  File "E:\DemandForecast\Backend\venv\lib\site-packages\django\core\handlers\exception.py", line 34, in inner
    response = get_response(request)
  File "E:\DemandForecast\Backend\venv\lib\site-packages\django\core\handlers\base.py", line 115, in _get_response
    response = self.process_exception_by_middleware(e, request)
  File "E:\DemandForecast\Backend\venv\lib\site-packages\django\core\handlers\base.py", line 113, in _get_response
    response = wrapped_callback(request, *callback_args, **callback_kwargs)
  File "E:\DemandForecast\Backend\venv\lib\site-packages\django\views\decorators\csrf.py", line 54, in wrapped_view
    return view_func(*args, **kwargs)
  File "E:\DemandForecast\Backend\venv\lib\site-packages\django\views\generic\base.py", line 71, in view
    return self.dispatch(request, *args, **kwargs)
  File "E:\DemandForecast\Backend\venv\lib\site-packages\rest_framework\views.py", line 505, in dispatch
    response = self.handle_exception(exc)
  File "E:\DemandForecast\Backend\venv\lib\site-packages\rest_framework\views.py", line 465, in handle_exception
    self.raise_uncaught_exception(exc)
  File "E:\DemandForecast\Backend\venv\lib\site-packages\rest_framework\views.py", line 476, in raise_uncaught_exception
    raise exc
  File "E:\DemandForecast\Backend\venv\lib\site-packages\rest_framework\views.py", line 502, in dispatch
    response = handler(request, *args, **kwargs)
  File "E:\DemandForecast\Backend\.\datas\views\chartViews.py", line 220, in get
    names = ['Total', str(columns[4]) + '-' + str(columns[7]), str(columns[8]) + '-' + str(columns[11]), 'End']
IndexError: list index out of range
ERROR  2025-07-31 10:37:19,580  D:\DemandForecast\DFBackend\venv97\lib\site-packages\django\utils\log.py  log  222  500  Internal Server Error: /cpastokechartdata/ 
Traceback (most recent call last):
  File "D:\DemandForecast\DFBackend\venv97\lib\site-packages\django\core\handlers\exception.py", line 34, in inner
    response = get_response(request)
  File "D:\DemandForecast\DFBackend\venv97\lib\site-packages\django\core\handlers\base.py", line 115, in _get_response
    response = self.process_exception_by_middleware(e, request)
  File "D:\DemandForecast\DFBackend\venv97\lib\site-packages\django\core\handlers\base.py", line 113, in _get_response
    response = wrapped_callback(request, *callback_args, **callback_kwargs)
  File "D:\DemandForecast\DFBackend\venv97\lib\site-packages\django\views\decorators\csrf.py", line 54, in wrapped_view
    return view_func(*args, **kwargs)
  File "D:\DemandForecast\DFBackend\venv97\lib\site-packages\django\views\generic\base.py", line 71, in view
    return self.dispatch(request, *args, **kwargs)
  File "D:\DemandForecast\DFBackend\venv97\lib\site-packages\rest_framework\views.py", line 505, in dispatch
    response = self.handle_exception(exc)
  File "D:\DemandForecast\DFBackend\venv97\lib\site-packages\rest_framework\views.py", line 465, in handle_exception
    self.raise_uncaught_exception(exc)
  File "D:\DemandForecast\DFBackend\venv97\lib\site-packages\rest_framework\views.py", line 476, in raise_uncaught_exception
    raise exc
  File "D:\DemandForecast\DFBackend\venv97\lib\site-packages\rest_framework\views.py", line 502, in dispatch
    response = handler(request, *args, **kwargs)
  File "D:\DemandForecast\DFBackend\datas\views\chartViews.py", line 220, in get
    names = ['Total', str(columns[4]) + '-' + str(columns[7]), str(columns[8]) + '-' + str(columns[11]), 'End']
IndexError: list index out of range
